<?xml version="1.0"?>
<robot name="robot">

    <material name="white">
        <color rgba="1 1 1 1"/>
    </material>

    <material name="orange">
        <color rgba="1 0.3 0.1 1"/>
    </material>

    <material name="blue">
        <color rgba="0.2 0.2 1 1"/>
    </material>

    <material name="black">
        <color rgba="0 0 0 1"/>
    </material>

    <!-- BASE LINK -->

    <link name="base_link">
        <visual>
            <origin xyz="-0.125 0.125 0" rpy="${pi/2} 0 0"/>
            <geometry>
                <mesh filename="package://droid/description/meshes/arm2/ground_link.STL" scale="0.001 0.001 0.001"/>
            </geometry>
            <material name="white"/>
        </visual>
        <collision>
            <origin xyz="-0.125 0.125 0" rpy="${pi/2} 0 0"/>
            <geometry>
                <mesh filename="package://droid/description/meshes/arm2/ground_link.STL" scale="0.001 0.001 0.001"/>
            </geometry>
        </collision>
    </link>

    <!-- LINK 1 -->

    <joint name="link1" type="revolute">
        <parent link="base_link"/>
        <child link="link1"/>
        <origin xyz="0 0 0.05" rpy="0 0 0"/>
        <axis xyz="0 0 1"/>
        <limit lower="${-pi}" upper="${pi}" velocity="100" effort="100"/>
    </joint>

    <link name="link1">
        <visual>
            <origin xyz="-0.125 0.125 0" rpy="${pi/2} 0 0"/>
            <geometry>
                <mesh filename="package://droid/description/meshes/arm1/link_1.STL" scale="0.001 0.001 0.001"/>
            </geometry>
            <material name="white"/>
        </visual>
        <collision>
            <origin xyz="-0.125 0.125 0" rpy="${pi/2} 0 0"/>
            <geometry>
                <mesh filename="package://droid/description/meshes/arm1/link_1.STL" scale="0.001 0.001 0.001"/>
            </geometry>
        </collision>
    </link>

    <!-- LINK 2 -->

    <joint name="link2" type="revolute">
        <parent link="link1"/>
        <child link="link2"/>
        <origin xyz="0 0 0.160" rpy="0 ${pi/2} 0"/>
        <axis xyz="0 0 1"/>
        <limit lower="${-0.75*pi}" upper="${0.75*pi}" velocity="100" effort="100"/>
    </joint>

    <link name="link2">
        <visual>
            <origin xyz="0.1 -0.125 -0.125" rpy="0 0 ${pi/2}"/>
            <geometry>
                <mesh filename="package://droid/description/meshes/arm1/link_2.STL" scale="0.001 0.001 0.001"/>
            </geometry>
            <material name="white"/>
        </visual>
        <collision>
            <origin xyz="0.1 -0.125 -0.125" rpy="0 0 ${pi/2}"/>
            <geometry>
                <mesh filename="package://droid/description/meshes/arm1/link_2.STL" scale="0.001 0.001 0.001"/>
            </geometry>
        </collision>
    </link>

    <!-- LINK 3 -->

    <joint name="link3" type="revolute">
        <parent link="link2"/>
        <child link="link3"/>
        <origin xyz="-1 0 0" rpy="0 0 0"/>
        <axis xyz="0 0 1"/>
        <limit lower="${-0.75*pi}" upper="${0.75*pi}" velocity="100" effort="100"/>
    </joint>

    <link name="link3">
        <visual>
            <origin xyz="0.35099 -1.28141 0.6489" rpy="0 ${pi/2} ${pi/2}"/>
            <geometry>
                <mesh filename="package://droid/description/meshes/arm1/link3_v2.STL" scale="0.001 0.001 0.001"/>
            </geometry>
            <material name="white"/>
        </visual>
        <collision>
            <origin xyz="0.35099 -1.28141 0.6489" rpy="0 ${pi/2} ${pi/2}"/>
            <geometry>
                <mesh filename="package://droid/description/meshes/arm1/link3_v2.STL" scale="0.001 0.001 0.001"/>
            </geometry>
        </collision>
    </link>

    <!-- LINK 4 -->

    <joint name="link4" type="revolute">
        <parent link="link3"/>
        <child link="link4"/>
        <origin xyz="-1.04 0 0" rpy="0 0 0"/>
        <axis xyz="0 0 1"/>
        <limit lower="${-0.75*pi}" upper="${0.75*pi}" velocity="100" effort="100"/>
    </joint>

    <link name="link4">
        <visual>
            <origin xyz="0.06 -0.075 0.075" rpy="0 ${pi/2} ${pi/2}"/>
            <geometry>
                <mesh filename="package://droid/description/meshes/arm1/link_4.STL" scale="0.001 0.001 0.001"/>
            </geometry>
            <material name="white"/>
        </visual>
        <collision>
            <origin xyz="0.06 -0.075 0.075" rpy="0 ${pi/2} ${pi/2}"/>
            <geometry>
                <mesh filename="package://droid/description/meshes/arm1/link_4.STL" scale="0.001 0.001 0.001"/>
            </geometry>
        </collision>
    </link>

    <!-- LINK 5 -->

    <joint name="link5" type="revolute">
        <parent link="link4"/>
        <child link="link5"/>
        <origin xyz="-0.18 0 0" rpy="0 ${-pi/2} 0"/>
        <axis xyz="0 0 1"/>
        <limit lower="${-pi}" upper="${pi}" velocity="100" effort="100"/>
    </joint>

    <link name="link5">
        <visual>
            <origin xyz="0.075 0.075 0" rpy="${pi/2} 0 ${-pi/2}"/>
            <geometry>
                <mesh filename="package://droid/description/meshes/arm1/link_5.STL" scale="0.001 0.001 0.001"/>
            </geometry>
            <material name="white"/>
        </visual>
        <collision>
            <origin xyz="0.075 0.075 0" rpy="${pi/2} 0 ${-pi/2}"/>
            <geometry>
                <mesh filename="package://droid/description/meshes/arm1/link_5.STL" scale="0.001 0.001 0.001"/>
            </geometry>
        </collision>
    </link>

    <!-- END EFFECTOR -->

    <joint name="ee" type="revolute">
        <parent link="link5"/>
        <child link="ee"/>
        <origin xyz="0 0 0.12" rpy="0 ${pi/2} 0"/>
        <axis xyz="0 0 1"/>
        <limit lower="${-pi/2}" upper="${pi/2}" velocity="100" effort="100"/>
    </joint>

    <link name="ee">
        <visual>
            <origin xyz="-1.6571 -0.65058 -0.85865" rpy="${pi/2} 0 ${pi/2}"/>
            <geometry>
                <mesh filename="package://droid/description/meshes/arm1/ee_v2.STL" scale="0.001 0.001 0.001"/>
            </geometry>
            <material name="white"/>
        </visual>
        <collision>
            <origin xyz="-1.6571 -0.65058 -0.85865" rpy="${pi/2} 0 ${pi/2}"/>
            <geometry>
                <mesh filename="package://droid/description/meshes/arm1/ee_v2.STL" scale="0.001 0.001 0.001"/>
            </geometry>
        </collision>
    </link>

</robot>